[2025-03-14T16:05:51.766+0000] {scheduler_job_runner.py:781} ERROR - Executor reports task instance <TaskInstance: gen_data_daily.run_script scheduled__2025-03-10T22:00:00+00:00 [queued]> finished (failed) although the task says it's queued. (Info: None) Was the task killed externally?
