[2025-03-17T14:49:50.738+0000] {scheduler_job_runner.py:781} ERROR - Executor reports task instance <TaskInstance: gen_data_daily.get_date scheduled__2025-03-14T22:00:00+00:00 [queued]> finished (failed) although the task says it's queued. (Info: None) Was the task killed externally?
