[2025-03-22T18:16:44.972+0000] {taskinstance.py:1957} INFO - Dependencies all met for dep_context=non-requeueable deps ti=<TaskInstance: gen_data_daily.gen_data_daily scheduled__2025-03-07T22:00:00+00:00 [queued]>
[2025-03-22T18:16:44.990+0000] {taskinstance.py:1957} INFO - Dependencies all met for dep_context=requeueable deps ti=<TaskInstance: gen_data_daily.gen_data_daily scheduled__2025-03-07T22:00:00+00:00 [queued]>
[2025-03-22T18:16:44.990+0000] {taskinstance.py:2171} INFO - Starting attempt 1 of 2
[2025-03-22T18:16:45.017+0000] {taskinstance.py:2192} INFO - Executing <Task(BashOperator): gen_data_daily> on 2025-03-07 22:00:00+00:00
[2025-03-22T18:16:45.025+0000] {standard_task_runner.py:60} INFO - Started process 5910 to run task
[2025-03-22T18:16:45.031+0000] {standard_task_runner.py:87} INFO - Running: ['***', 'tasks', 'run', 'gen_data_daily', 'gen_data_daily', 'scheduled__2025-03-07T22:00:00+00:00', '--job-id', '24', '--raw', '--subdir', 'DAGS_FOLDER/gen_data_daily.py', '--cfg-path', '/tmp/tmplrl6lrsv']
[2025-03-22T18:16:45.033+0000] {standard_task_runner.py:88} INFO - Job 24: Subtask gen_data_daily
[2025-03-22T18:16:45.234+0000] {task_command.py:423} INFO - Running <TaskInstance: gen_data_daily.gen_data_daily scheduled__2025-03-07T22:00:00+00:00 [running]> on host 8d12aff548d4
[2025-03-22T18:16:45.468+0000] {taskinstance.py:2481} INFO - Exporting env vars: AIRFLOW_CTX_DAG_OWNER='longnv' AIRFLOW_CTX_DAG_ID='gen_data_daily' AIRFLOW_CTX_TASK_ID='gen_data_daily' AIRFLOW_CTX_EXECUTION_DATE='2025-03-07T22:00:00+00:00' AIRFLOW_CTX_TRY_NUMBER='1' AIRFLOW_CTX_DAG_RUN_ID='scheduled__2025-03-07T22:00:00+00:00'
[2025-03-22T18:16:45.471+0000] {subprocess.py:63} INFO - Tmp dir root location: /tmp
[2025-03-22T18:16:45.472+0000] {subprocess.py:75} INFO - Running command: ['/usr/bin/bash', '-c', '\n        python /opt/***/external_scripts/1_gen_transaction_data.py 2025-03-08\n        ']
[2025-03-22T18:16:45.498+0000] {subprocess.py:86} INFO - Output:
[2025-03-22T18:16:46.658+0000] {subprocess.py:93} INFO - Traceback (most recent call last):
[2025-03-22T18:16:46.660+0000] {subprocess.py:93} INFO -   File "/home/***/.local/lib/python3.8/site-packages/sqlalchemy/engine/base.py", line 3371, in _wrap_pool_connect
[2025-03-22T18:16:46.661+0000] {subprocess.py:93} INFO -     return fn()
[2025-03-22T18:16:46.662+0000] {subprocess.py:93} INFO -   File "/home/***/.local/lib/python3.8/site-packages/sqlalchemy/pool/base.py", line 327, in connect
[2025-03-22T18:16:46.663+0000] {subprocess.py:93} INFO -     return _ConnectionFairy._checkout(self)
[2025-03-22T18:16:46.664+0000] {subprocess.py:93} INFO -   File "/home/***/.local/lib/python3.8/site-packages/sqlalchemy/pool/base.py", line 894, in _checkout
[2025-03-22T18:16:46.665+0000] {subprocess.py:93} INFO -     fairy = _ConnectionRecord.checkout(pool)
[2025-03-22T18:16:46.669+0000] {subprocess.py:93} INFO -   File "/home/***/.local/lib/python3.8/site-packages/sqlalchemy/pool/base.py", line 493, in checkout
[2025-03-22T18:16:46.669+0000] {subprocess.py:93} INFO -     rec = pool._do_get()
[2025-03-22T18:16:46.669+0000] {subprocess.py:93} INFO -   File "/home/***/.local/lib/python3.8/site-packages/sqlalchemy/pool/impl.py", line 146, in _do_get
[2025-03-22T18:16:46.669+0000] {subprocess.py:93} INFO -     self._dec_overflow()
[2025-03-22T18:16:46.669+0000] {subprocess.py:93} INFO -   File "/home/***/.local/lib/python3.8/site-packages/sqlalchemy/util/langhelpers.py", line 70, in __exit__
[2025-03-22T18:16:46.670+0000] {subprocess.py:93} INFO -     compat.raise_(
[2025-03-22T18:16:46.671+0000] {subprocess.py:93} INFO -   File "/home/***/.local/lib/python3.8/site-packages/sqlalchemy/util/compat.py", line 211, in raise_
[2025-03-22T18:16:46.672+0000] {subprocess.py:93} INFO -     raise exception
[2025-03-22T18:16:46.674+0000] {subprocess.py:93} INFO -   File "/home/***/.local/lib/python3.8/site-packages/sqlalchemy/pool/impl.py", line 143, in _do_get
[2025-03-22T18:16:46.681+0000] {subprocess.py:93} INFO -     return self._create_connection()
[2025-03-22T18:16:46.682+0000] {subprocess.py:93} INFO -   File "/home/***/.local/lib/python3.8/site-packages/sqlalchemy/pool/base.py", line 273, in _create_connection
[2025-03-22T18:16:46.682+0000] {subprocess.py:93} INFO -     return _ConnectionRecord(self)
[2025-03-22T18:16:46.683+0000] {subprocess.py:93} INFO -   File "/home/***/.local/lib/python3.8/site-packages/sqlalchemy/pool/base.py", line 388, in __init__
[2025-03-22T18:16:46.688+0000] {subprocess.py:93} INFO -     self.__connect()
[2025-03-22T18:16:46.688+0000] {subprocess.py:93} INFO -   File "/home/***/.local/lib/python3.8/site-packages/sqlalchemy/pool/base.py", line 691, in __connect
[2025-03-22T18:16:46.688+0000] {subprocess.py:93} INFO -     pool.logger.debug("Error on connect(): %s", e)
[2025-03-22T18:16:46.688+0000] {subprocess.py:93} INFO -   File "/home/***/.local/lib/python3.8/site-packages/sqlalchemy/util/langhelpers.py", line 70, in __exit__
[2025-03-22T18:16:46.689+0000] {subprocess.py:93} INFO -     compat.raise_(
[2025-03-22T18:16:46.689+0000] {subprocess.py:93} INFO -   File "/home/***/.local/lib/python3.8/site-packages/sqlalchemy/util/compat.py", line 211, in raise_
[2025-03-22T18:16:46.689+0000] {subprocess.py:93} INFO -     raise exception
[2025-03-22T18:16:46.689+0000] {subprocess.py:93} INFO -   File "/home/***/.local/lib/python3.8/site-packages/sqlalchemy/pool/base.py", line 686, in __connect
[2025-03-22T18:16:46.689+0000] {subprocess.py:93} INFO -     self.dbapi_connection = connection = pool._invoke_creator(self)
[2025-03-22T18:16:46.689+0000] {subprocess.py:93} INFO -   File "/home/***/.local/lib/python3.8/site-packages/sqlalchemy/engine/create.py", line 574, in connect
[2025-03-22T18:16:46.689+0000] {subprocess.py:93} INFO -     return dialect.connect(*cargs, **cparams)
[2025-03-22T18:16:46.689+0000] {subprocess.py:93} INFO -   File "/home/***/.local/lib/python3.8/site-packages/sqlalchemy/engine/default.py", line 598, in connect
[2025-03-22T18:16:46.690+0000] {subprocess.py:93} INFO -     return self.dbapi.connect(*cargs, **cparams)
[2025-03-22T18:16:46.690+0000] {subprocess.py:93} INFO -   File "/home/***/.local/lib/python3.8/site-packages/psycopg2/__init__.py", line 122, in connect
[2025-03-22T18:16:46.690+0000] {subprocess.py:93} INFO -     conn = _connect(dsn, connection_factory=connection_factory, **kwasync)
[2025-03-22T18:16:46.691+0000] {subprocess.py:93} INFO - psycopg2.OperationalError: connection to server at "localhost" (::1), port 5432 failed: Connection refused
[2025-03-22T18:16:46.691+0000] {subprocess.py:93} INFO - 	Is the server running on that host and accepting TCP/IP connections?
[2025-03-22T18:16:46.691+0000] {subprocess.py:93} INFO - connection to server at "localhost" (127.0.0.1), port 5432 failed: Connection refused
[2025-03-22T18:16:46.696+0000] {subprocess.py:93} INFO - 	Is the server running on that host and accepting TCP/IP connections?
[2025-03-22T18:16:46.699+0000] {subprocess.py:93} INFO - 
[2025-03-22T18:16:46.699+0000] {subprocess.py:93} INFO - 
[2025-03-22T18:16:46.699+0000] {subprocess.py:93} INFO - The above exception was the direct cause of the following exception:
[2025-03-22T18:16:46.699+0000] {subprocess.py:93} INFO - 
[2025-03-22T18:16:46.700+0000] {subprocess.py:93} INFO - Traceback (most recent call last):
[2025-03-22T18:16:46.700+0000] {subprocess.py:93} INFO -   File "/opt/***/external_scripts/1_gen_transaction_data.py", line 100, in <module>
[2025-03-22T18:16:46.700+0000] {subprocess.py:93} INFO -     insert_data_to_postgres(df, table_name="transaction_data")
[2025-03-22T18:16:46.701+0000] {subprocess.py:93} INFO -   File "/opt/***/external_scripts/1_gen_transaction_data.py", line 73, in insert_data_to_postgres
[2025-03-22T18:16:46.701+0000] {subprocess.py:93} INFO -     metadata.create_all(engine)
[2025-03-22T18:16:46.701+0000] {subprocess.py:93} INFO -   File "/home/***/.local/lib/python3.8/site-packages/sqlalchemy/sql/schema.py", line 4930, in create_all
[2025-03-22T18:16:46.701+0000] {subprocess.py:93} INFO -     bind._run_ddl_visitor(
[2025-03-22T18:16:46.702+0000] {subprocess.py:93} INFO -   File "/home/***/.local/lib/python3.8/site-packages/sqlalchemy/engine/base.py", line 3237, in _run_ddl_visitor
[2025-03-22T18:16:46.704+0000] {subprocess.py:93} INFO -     with self.begin() as conn:
[2025-03-22T18:16:46.704+0000] {subprocess.py:93} INFO -   File "/home/***/.local/lib/python3.8/site-packages/sqlalchemy/engine/base.py", line 3153, in begin
[2025-03-22T18:16:46.704+0000] {subprocess.py:93} INFO -     conn = self.connect(close_with_result=close_with_result)
[2025-03-22T18:16:46.704+0000] {subprocess.py:93} INFO -   File "/home/***/.local/lib/python3.8/site-packages/sqlalchemy/engine/base.py", line 3325, in connect
[2025-03-22T18:16:46.704+0000] {subprocess.py:93} INFO -     return self._connection_cls(self, close_with_result=close_with_result)
[2025-03-22T18:16:46.704+0000] {subprocess.py:93} INFO -   File "/home/***/.local/lib/python3.8/site-packages/sqlalchemy/engine/base.py", line 96, in __init__
[2025-03-22T18:16:46.704+0000] {subprocess.py:93} INFO -     else engine.raw_connection()
[2025-03-22T18:16:46.704+0000] {subprocess.py:93} INFO -   File "/home/***/.local/lib/python3.8/site-packages/sqlalchemy/engine/base.py", line 3404, in raw_connection
[2025-03-22T18:16:46.705+0000] {subprocess.py:93} INFO -     return self._wrap_pool_connect(self.pool.connect, _connection)
[2025-03-22T18:16:46.705+0000] {subprocess.py:93} INFO -   File "/home/***/.local/lib/python3.8/site-packages/sqlalchemy/engine/base.py", line 3374, in _wrap_pool_connect
[2025-03-22T18:16:46.705+0000] {subprocess.py:93} INFO -     Connection._handle_dbapi_exception_noconnection(
[2025-03-22T18:16:46.709+0000] {subprocess.py:93} INFO -   File "/home/***/.local/lib/python3.8/site-packages/sqlalchemy/engine/base.py", line 2208, in _handle_dbapi_exception_noconnection
[2025-03-22T18:16:46.709+0000] {subprocess.py:93} INFO -     util.raise_(
[2025-03-22T18:16:46.711+0000] {subprocess.py:93} INFO -   File "/home/***/.local/lib/python3.8/site-packages/sqlalchemy/util/compat.py", line 211, in raise_
[2025-03-22T18:16:46.712+0000] {subprocess.py:93} INFO -     raise exception
[2025-03-22T18:16:46.712+0000] {subprocess.py:93} INFO -   File "/home/***/.local/lib/python3.8/site-packages/sqlalchemy/engine/base.py", line 3371, in _wrap_pool_connect
[2025-03-22T18:16:46.712+0000] {subprocess.py:93} INFO -     return fn()
[2025-03-22T18:16:46.712+0000] {subprocess.py:93} INFO -   File "/home/***/.local/lib/python3.8/site-packages/sqlalchemy/pool/base.py", line 327, in connect
[2025-03-22T18:16:46.712+0000] {subprocess.py:93} INFO -     return _ConnectionFairy._checkout(self)
[2025-03-22T18:16:46.712+0000] {subprocess.py:93} INFO -   File "/home/***/.local/lib/python3.8/site-packages/sqlalchemy/pool/base.py", line 894, in _checkout
[2025-03-22T18:16:46.713+0000] {subprocess.py:93} INFO -     fairy = _ConnectionRecord.checkout(pool)
[2025-03-22T18:16:46.713+0000] {subprocess.py:93} INFO -   File "/home/***/.local/lib/python3.8/site-packages/sqlalchemy/pool/base.py", line 493, in checkout
[2025-03-22T18:16:46.713+0000] {subprocess.py:93} INFO -     rec = pool._do_get()
[2025-03-22T18:16:46.713+0000] {subprocess.py:93} INFO -   File "/home/***/.local/lib/python3.8/site-packages/sqlalchemy/pool/impl.py", line 146, in _do_get
[2025-03-22T18:16:46.716+0000] {subprocess.py:93} INFO -     self._dec_overflow()
[2025-03-22T18:16:46.717+0000] {subprocess.py:93} INFO -   File "/home/***/.local/lib/python3.8/site-packages/sqlalchemy/util/langhelpers.py", line 70, in __exit__
[2025-03-22T18:16:46.718+0000] {subprocess.py:93} INFO -     compat.raise_(
[2025-03-22T18:16:46.718+0000] {subprocess.py:93} INFO -   File "/home/***/.local/lib/python3.8/site-packages/sqlalchemy/util/compat.py", line 211, in raise_
[2025-03-22T18:16:46.720+0000] {subprocess.py:93} INFO -     raise exception
[2025-03-22T18:16:46.720+0000] {subprocess.py:93} INFO -   File "/home/***/.local/lib/python3.8/site-packages/sqlalchemy/pool/impl.py", line 143, in _do_get
[2025-03-22T18:16:46.720+0000] {subprocess.py:93} INFO -     return self._create_connection()
[2025-03-22T18:16:46.720+0000] {subprocess.py:93} INFO -   File "/home/***/.local/lib/python3.8/site-packages/sqlalchemy/pool/base.py", line 273, in _create_connection
[2025-03-22T18:16:46.721+0000] {subprocess.py:93} INFO -     return _ConnectionRecord(self)
[2025-03-22T18:16:46.721+0000] {subprocess.py:93} INFO -   File "/home/***/.local/lib/python3.8/site-packages/sqlalchemy/pool/base.py", line 388, in __init__
[2025-03-22T18:16:46.722+0000] {subprocess.py:93} INFO -     self.__connect()
[2025-03-22T18:16:46.722+0000] {subprocess.py:93} INFO -   File "/home/***/.local/lib/python3.8/site-packages/sqlalchemy/pool/base.py", line 691, in __connect
[2025-03-22T18:16:46.722+0000] {subprocess.py:93} INFO -     pool.logger.debug("Error on connect(): %s", e)
[2025-03-22T18:16:46.722+0000] {subprocess.py:93} INFO -   File "/home/***/.local/lib/python3.8/site-packages/sqlalchemy/util/langhelpers.py", line 70, in __exit__
[2025-03-22T18:16:46.722+0000] {subprocess.py:93} INFO -     compat.raise_(
[2025-03-22T18:16:46.722+0000] {subprocess.py:93} INFO -   File "/home/***/.local/lib/python3.8/site-packages/sqlalchemy/util/compat.py", line 211, in raise_
[2025-03-22T18:16:46.722+0000] {subprocess.py:93} INFO -     raise exception
[2025-03-22T18:16:46.722+0000] {subprocess.py:93} INFO -   File "/home/***/.local/lib/python3.8/site-packages/sqlalchemy/pool/base.py", line 686, in __connect
[2025-03-22T18:16:46.722+0000] {subprocess.py:93} INFO -     self.dbapi_connection = connection = pool._invoke_creator(self)
[2025-03-22T18:16:46.723+0000] {subprocess.py:93} INFO -   File "/home/***/.local/lib/python3.8/site-packages/sqlalchemy/engine/create.py", line 574, in connect
[2025-03-22T18:16:46.723+0000] {subprocess.py:93} INFO -     return dialect.connect(*cargs, **cparams)
[2025-03-22T18:16:46.723+0000] {subprocess.py:93} INFO -   File "/home/***/.local/lib/python3.8/site-packages/sqlalchemy/engine/default.py", line 598, in connect
[2025-03-22T18:16:46.723+0000] {subprocess.py:93} INFO -     return self.dbapi.connect(*cargs, **cparams)
[2025-03-22T18:16:46.724+0000] {subprocess.py:93} INFO -   File "/home/***/.local/lib/python3.8/site-packages/psycopg2/__init__.py", line 122, in connect
[2025-03-22T18:16:46.728+0000] {subprocess.py:93} INFO -     conn = _connect(dsn, connection_factory=connection_factory, **kwasync)
[2025-03-22T18:16:46.729+0000] {subprocess.py:93} INFO - sqlalchemy.exc.OperationalError: (psycopg2.OperationalError) connection to server at "localhost" (::1), port 5432 failed: Connection refused
[2025-03-22T18:16:46.729+0000] {subprocess.py:93} INFO - 	Is the server running on that host and accepting TCP/IP connections?
[2025-03-22T18:16:46.729+0000] {subprocess.py:93} INFO - connection to server at "localhost" (127.0.0.1), port 5432 failed: Connection refused
[2025-03-22T18:16:46.730+0000] {subprocess.py:93} INFO - 	Is the server running on that host and accepting TCP/IP connections?
[2025-03-22T18:16:46.730+0000] {subprocess.py:93} INFO - 
[2025-03-22T18:16:46.730+0000] {subprocess.py:93} INFO - (Background on this error at: https://sqlalche.me/e/14/e3q8)
[2025-03-22T18:16:46.841+0000] {subprocess.py:97} INFO - Command exited with return code 1
[2025-03-22T18:16:46.862+0000] {taskinstance.py:2699} ERROR - Task failed with exception
Traceback (most recent call last):
  File "/home/airflow/.local/lib/python3.8/site-packages/airflow/models/taskinstance.py", line 433, in _execute_task
    result = execute_callable(context=context, **execute_callable_kwargs)
  File "/home/airflow/.local/lib/python3.8/site-packages/airflow/operators/bash.py", line 212, in execute
    raise AirflowException(
airflow.exceptions.AirflowException: Bash command failed. The command returned a non-zero exit code 1.
[2025-03-22T18:16:46.870+0000] {taskinstance.py:1138} INFO - Marking task as UP_FOR_RETRY. dag_id=gen_data_daily, task_id=gen_data_daily, execution_date=20250307T220000, start_date=20250322T181644, end_date=20250322T181646
[2025-03-22T18:16:46.897+0000] {standard_task_runner.py:107} ERROR - Failed to execute job 24 for task gen_data_daily (Bash command failed. The command returned a non-zero exit code 1.; 5910)
[2025-03-22T18:16:46.915+0000] {local_task_job_runner.py:234} INFO - Task exited with return code 1
[2025-03-22T18:16:46.954+0000] {taskinstance.py:3281} INFO - 0 downstream tasks scheduled from follow-on schedule check
