[2025-03-14T18:14:02.985+0000] {taskinstance.py:1957} INFO - Dependencies all met for dep_context=non-requeueable deps ti=<TaskInstance: gen_data_daily.run_script manual__2025-03-14T17:32:07.165897+00:00 [queued]>
[2025-03-14T18:14:02.998+0000] {taskinstance.py:1957} INFO - Dependencies all met for dep_context=requeueable deps ti=<TaskInstance: gen_data_daily.run_script manual__2025-03-14T17:32:07.165897+00:00 [queued]>
[2025-03-14T18:14:02.998+0000] {taskinstance.py:2171} INFO - Starting attempt 3 of 4
[2025-03-14T18:14:03.013+0000] {taskinstance.py:2192} INFO - Executing <Task(BashOperator): run_script> on 2025-03-14 17:32:07.165897+00:00
[2025-03-14T18:14:03.020+0000] {standard_task_runner.py:60} INFO - Started process 804 to run task
[2025-03-14T18:14:03.023+0000] {standard_task_runner.py:87} INFO - Running: ['***', 'tasks', 'run', 'gen_data_daily', 'run_script', 'manual__2025-03-14T17:32:07.165897+00:00', '--job-id', '6', '--raw', '--subdir', 'DAGS_FOLDER/gen_data_daily.py', '--cfg-path', '/tmp/tmpi18u075d']
[2025-03-14T18:14:03.024+0000] {standard_task_runner.py:88} INFO - Job 6: Subtask run_script
[2025-03-14T18:14:03.098+0000] {task_command.py:423} INFO - Running <TaskInstance: gen_data_daily.run_script manual__2025-03-14T17:32:07.165897+00:00 [running]> on host e9f75e17acd8
[2025-03-14T18:14:03.208+0000] {taskinstance.py:2481} INFO - Exporting env vars: AIRFLOW_CTX_DAG_OWNER='longnv' AIRFLOW_CTX_DAG_ID='gen_data_daily' AIRFLOW_CTX_TASK_ID='run_script' AIRFLOW_CTX_EXECUTION_DATE='2025-03-14T17:32:07.165897+00:00' AIRFLOW_CTX_TRY_NUMBER='3' AIRFLOW_CTX_DAG_RUN_ID='manual__2025-03-14T17:32:07.165897+00:00'
[2025-03-14T18:14:03.212+0000] {subprocess.py:63} INFO - Tmp dir root location: /tmp
[2025-03-14T18:14:03.212+0000] {subprocess.py:75} INFO - Running command: ['/usr/bin/bash', '-c', '\n        python /opt/***/external_scripts/gen_transaction_data.py 2025-03-15\n        ']
[2025-03-14T18:14:03.232+0000] {subprocess.py:86} INFO - Output:
[2025-03-14T18:14:04.248+0000] {subprocess.py:93} INFO - INFO:kafka.conn:<BrokerConnection node_id=bootstrap-0 host=localhost:9092 <connecting> [IPv6 ('::1', 9092, 0, 0)]>: connecting to localhost:9092 [('::1', 9092, 0, 0) IPv6]
[2025-03-14T18:14:04.249+0000] {subprocess.py:93} INFO - INFO:kafka.conn:Probing node bootstrap-0 broker version
[2025-03-14T18:14:04.249+0000] {subprocess.py:93} INFO - ERROR:kafka.conn:Connect attempt to <BrokerConnection node_id=bootstrap-0 host=localhost:9092 <connecting> [IPv6 ('::1', 9092, 0, 0)]> returned error 111. Disconnecting.
[2025-03-14T18:14:04.250+0000] {subprocess.py:93} INFO - INFO:kafka.conn:<BrokerConnection node_id=bootstrap-0 host=localhost:9092 <connecting> [IPv6 ('::1', 9092, 0, 0)]>: Closing connection. KafkaConnectionError: 111 ECONNREFUSED
[2025-03-14T18:14:04.253+0000] {subprocess.py:93} INFO - INFO:kafka.conn:<BrokerConnection node_id=bootstrap-0 host=localhost:9092 <connecting> [IPv6 ('::1', 9092, 0, 0)]>: connecting to localhost:9092 [('::1', 9092, 0, 0) IPv6]
[2025-03-14T18:14:04.254+0000] {subprocess.py:93} INFO - ERROR:kafka.conn:Connect attempt to <BrokerConnection node_id=bootstrap-0 host=localhost:9092 <connecting> [IPv6 ('::1', 9092, 0, 0)]> returned error 111. Disconnecting.
[2025-03-14T18:14:04.254+0000] {subprocess.py:93} INFO - INFO:kafka.conn:<BrokerConnection node_id=bootstrap-0 host=localhost:9092 <connecting> [IPv6 ('::1', 9092, 0, 0)]>: Closing connection. KafkaConnectionError: 111 ECONNREFUSED
[2025-03-14T18:14:04.303+0000] {subprocess.py:93} INFO - INFO:kafka.conn:<BrokerConnection node_id=bootstrap-0 host=localhost:9092 <connecting> [IPv4 ('127.0.0.1', 9092)]>: connecting to localhost:9092 [('127.0.0.1', 9092) IPv4]
[2025-03-14T18:14:04.304+0000] {subprocess.py:93} INFO - ERROR:kafka.conn:Connect attempt to <BrokerConnection node_id=bootstrap-0 host=localhost:9092 <connecting> [IPv4 ('127.0.0.1', 9092)]> returned error 111. Disconnecting.
[2025-03-14T18:14:04.304+0000] {subprocess.py:93} INFO - INFO:kafka.conn:<BrokerConnection node_id=bootstrap-0 host=localhost:9092 <connecting> [IPv4 ('127.0.0.1', 9092)]>: Closing connection. KafkaConnectionError: 111 ECONNREFUSED
[2025-03-14T18:14:04.304+0000] {subprocess.py:93} INFO - Data retrieved! (20000, 6)
[2025-03-14T18:14:04.304+0000] {subprocess.py:93} INFO - Data saved! /tmp/***tmpx18xhayl
[2025-03-14T18:14:04.318+0000] {subprocess.py:93} INFO - Traceback (most recent call last):
[2025-03-14T18:14:04.318+0000] {subprocess.py:93} INFO -   File "/opt/***/external_scripts/gen_transaction_data.py", line 160, in <module>
[2025-03-14T18:14:04.319+0000] {subprocess.py:93} INFO -     ingest_data_to_kafka(df, "crypto_data", batch_size=100)
[2025-03-14T18:14:04.319+0000] {subprocess.py:93} INFO -   File "/opt/***/external_scripts/gen_transaction_data.py", line 102, in ingest_data_to_kafka
[2025-03-14T18:14:04.319+0000] {subprocess.py:93} INFO -     admin_client = KafkaAdminClient(
[2025-03-14T18:14:04.319+0000] {subprocess.py:93} INFO -   File "/home/***/.local/lib/python3.8/site-packages/kafka/admin/client.py", line 208, in __init__
[2025-03-14T18:14:04.319+0000] {subprocess.py:93} INFO -     self._client = KafkaClient(metrics=self._metrics,
[2025-03-14T18:14:04.319+0000] {subprocess.py:93} INFO -   File "/home/***/.local/lib/python3.8/site-packages/kafka/client_async.py", line 244, in __init__
[2025-03-14T18:14:04.320+0000] {subprocess.py:93} INFO -     self.config['api_version'] = self.check_version(timeout=check_timeout)
[2025-03-14T18:14:04.320+0000] {subprocess.py:93} INFO -   File "/home/***/.local/lib/python3.8/site-packages/kafka/client_async.py", line 900, in check_version
[2025-03-14T18:14:04.320+0000] {subprocess.py:93} INFO -     raise Errors.NoBrokersAvailable()
[2025-03-14T18:14:04.320+0000] {subprocess.py:93} INFO - kafka.errors.NoBrokersAvailable: NoBrokersAvailable
[2025-03-14T18:14:04.408+0000] {subprocess.py:97} INFO - Command exited with return code 1
[2025-03-14T18:14:04.428+0000] {taskinstance.py:2699} ERROR - Task failed with exception
Traceback (most recent call last):
  File "/home/airflow/.local/lib/python3.8/site-packages/airflow/models/taskinstance.py", line 433, in _execute_task
    result = execute_callable(context=context, **execute_callable_kwargs)
  File "/home/airflow/.local/lib/python3.8/site-packages/airflow/operators/bash.py", line 212, in execute
    raise AirflowException(
airflow.exceptions.AirflowException: Bash command failed. The command returned a non-zero exit code 1.
[2025-03-14T18:14:04.460+0000] {taskinstance.py:1138} INFO - Marking task as UP_FOR_RETRY. dag_id=gen_data_daily, task_id=run_script, execution_date=20250314T173207, start_date=20250314T181402, end_date=20250314T181404
[2025-03-14T18:14:04.518+0000] {standard_task_runner.py:107} ERROR - Failed to execute job 6 for task run_script (Bash command failed. The command returned a non-zero exit code 1.; 804)
[2025-03-14T18:14:04.560+0000] {local_task_job_runner.py:234} INFO - Task exited with return code 1
[2025-03-14T18:14:04.599+0000] {taskinstance.py:3281} INFO - 0 downstream tasks scheduled from follow-on schedule check
